2024-03-27 04:10:32,928 INFO Watching for file changes with StatReloader
2024-03-27 04:10:45,110 ERROR Internal Server Error: /api/search/
Traceback (most recent call last):
  File "c:\Users\Shamrock\Desktop\mangalib_monster обход блокировки ботов\.venv\lib\site-packages\django\core\handlers\exception.py", line 55, in inner
    response = get_response(request)
  File "c:\Users\Shamrock\Desktop\mangalib_monster обход блокировки ботов\.venv\lib\site-packages\django\core\handlers\base.py", line 197, in _get_response
    response = wrapped_callback(request, *callback_args, **callback_kwargs)
  File "c:\Users\Shamrock\Desktop\mangalib_monster обход блокировки ботов\.venv\lib\site-packages\django\views\decorators\csrf.py", line 65, in _view_wrapper
    return view_func(request, *args, **kwargs)
  File "c:\Users\Shamrock\Desktop\mangalib_monster обход блокировки ботов\.venv\lib\site-packages\django\views\generic\base.py", line 104, in view
    return self.dispatch(request, *args, **kwargs)
  File "c:\Users\Shamrock\Desktop\mangalib_monster обход блокировки ботов\.venv\lib\site-packages\rest_framework\views.py", line 509, in dispatch
    response = self.handle_exception(exc)
  File "c:\Users\Shamrock\Desktop\mangalib_monster обход блокировки ботов\.venv\lib\site-packages\rest_framework\views.py", line 469, in handle_exception
    self.raise_uncaught_exception(exc)
  File "c:\Users\Shamrock\Desktop\mangalib_monster обход блокировки ботов\.venv\lib\site-packages\rest_framework\views.py", line 480, in raise_uncaught_exception
    raise exc
  File "c:\Users\Shamrock\Desktop\mangalib_monster обход блокировки ботов\.venv\lib\site-packages\rest_framework\views.py", line 506, in dispatch
    response = handler(request, *args, **kwargs)
  File "c:\Users\Shamrock\Desktop\mangalib_monster обход блокировки ботов\.venv\lib\site-packages\rest_framework\decorators.py", line 50, in handler
    return func(*args, **kwargs)
  File "C:\Users\Shamrock\Desktop\mangalib_monster обход блокировки ботов\monster\manga\views.py", line 40, in search
    manga_manager: BaseManager[Manga] = q_search(query).order_by('id')
  File "C:\Users\Shamrock\Desktop\mangalib_monster обход блокировки ботов\monster\manga\utils.py", line 39, in q_search
    result = result.filter(lambda manga: manga.get_all_comments().count()>0)
  File "c:\Users\Shamrock\Desktop\mangalib_monster обход блокировки ботов\.venv\lib\site-packages\django\db\models\query.py", line 1476, in filter
    return self._filter_or_exclude(False, args, kwargs)
  File "c:\Users\Shamrock\Desktop\mangalib_monster обход блокировки ботов\.venv\lib\site-packages\django\db\models\query.py", line 1494, in _filter_or_exclude
    clone._filter_or_exclude_inplace(negate, args, kwargs)
  File "c:\Users\Shamrock\Desktop\mangalib_monster обход блокировки ботов\.venv\lib\site-packages\django\db\models\query.py", line 1501, in _filter_or_exclude_inplace
    self._query.add_q(Q(*args, **kwargs))
  File "c:\Users\Shamrock\Desktop\mangalib_monster обход блокировки ботов\.venv\lib\site-packages\django\db\models\sql\query.py", line 1613, in add_q
    clause, _ = self._add_q(q_object, self.used_aliases)
  File "c:\Users\Shamrock\Desktop\mangalib_monster обход блокировки ботов\.venv\lib\site-packages\django\db\models\sql\query.py", line 1645, in _add_q
    child_clause, needed_inner = self.build_filter(
  File "c:\Users\Shamrock\Desktop\mangalib_monster обход блокировки ботов\.venv\lib\site-packages\django\db\models\sql\query.py", line 1492, in build_filter
    arg, value = filter_expr
TypeError: cannot unpack non-iterable function object
2024-03-27 04:13:26,053 DEBUG Using proactor: IocpProactor
2024-03-27 04:13:48,406 INFO C:\Users\Shamrock\Desktop\mangalib_monster обход блокировки ботов\monster\manga\utils.py changed, reloading.
2024-03-27 04:13:49,448 INFO Watching for file changes with StatReloader
2024-03-27 04:14:00,097 INFO C:\Users\Shamrock\Desktop\mangalib_monster обход блокировки ботов\monster\manga\utils.py changed, reloading.
2024-03-27 04:14:01,565 INFO Watching for file changes with StatReloader
2024-03-27 04:14:05,446 INFO C:\Users\Shamrock\Desktop\mangalib_monster обход блокировки ботов\monster\manga\utils.py changed, reloading.
2024-03-27 04:14:06,583 INFO Watching for file changes with StatReloader
2024-03-27 04:14:14,051 INFO C:\Users\Shamrock\Desktop\mangalib_monster обход блокировки ботов\monster\manga\utils.py changed, reloading.
2024-03-27 04:14:15,404 INFO Watching for file changes with StatReloader
2024-03-27 04:14:42,154 INFO C:\Users\Shamrock\Desktop\mangalib_monster обход блокировки ботов\monster\manga\utils.py changed, reloading.
2024-03-27 04:14:43,269 INFO Watching for file changes with StatReloader
2024-03-27 04:14:50,117 ERROR Internal Server Error: /api/search/
Traceback (most recent call last):
  File "c:\Users\Shamrock\Desktop\mangalib_monster обход блокировки ботов\.venv\lib\site-packages\django\core\handlers\exception.py", line 55, in inner
    response = get_response(request)
  File "c:\Users\Shamrock\Desktop\mangalib_monster обход блокировки ботов\.venv\lib\site-packages\django\core\handlers\base.py", line 197, in _get_response
    response = wrapped_callback(request, *callback_args, **callback_kwargs)
  File "c:\Users\Shamrock\Desktop\mangalib_monster обход блокировки ботов\.venv\lib\site-packages\django\views\decorators\csrf.py", line 65, in _view_wrapper
    return view_func(request, *args, **kwargs)
  File "c:\Users\Shamrock\Desktop\mangalib_monster обход блокировки ботов\.venv\lib\site-packages\django\views\generic\base.py", line 104, in view
    return self.dispatch(request, *args, **kwargs)
  File "c:\Users\Shamrock\Desktop\mangalib_monster обход блокировки ботов\.venv\lib\site-packages\rest_framework\views.py", line 509, in dispatch
    response = self.handle_exception(exc)
  File "c:\Users\Shamrock\Desktop\mangalib_monster обход блокировки ботов\.venv\lib\site-packages\rest_framework\views.py", line 469, in handle_exception
    self.raise_uncaught_exception(exc)
  File "c:\Users\Shamrock\Desktop\mangalib_monster обход блокировки ботов\.venv\lib\site-packages\rest_framework\views.py", line 480, in raise_uncaught_exception
    raise exc
  File "c:\Users\Shamrock\Desktop\mangalib_monster обход блокировки ботов\.venv\lib\site-packages\rest_framework\views.py", line 506, in dispatch
    response = handler(request, *args, **kwargs)
  File "c:\Users\Shamrock\Desktop\mangalib_monster обход блокировки ботов\.venv\lib\site-packages\rest_framework\decorators.py", line 50, in handler
    return func(*args, **kwargs)
  File "C:\Users\Shamrock\Desktop\mangalib_monster обход блокировки ботов\monster\manga\views.py", line 40, in search
    manga_manager: BaseManager[Manga] = q_search(query).order_by('id')
  File "C:\Users\Shamrock\Desktop\mangalib_monster обход блокировки ботов\monster\manga\utils.py", line 42, in q_search
    result = result.annotate(comments_num=Count('chapters__pages__comment')).filter(comments_num__gt=0)
  File "c:\Users\Shamrock\Desktop\mangalib_monster обход блокировки ботов\.venv\lib\site-packages\django\db\models\query.py", line 1630, in annotate
    return self._annotate(args, kwargs, select=True)
  File "c:\Users\Shamrock\Desktop\mangalib_monster обход блокировки ботов\.venv\lib\site-packages\django\db\models\query.py", line 1680, in _annotate
    clone.query.add_annotation(
  File "c:\Users\Shamrock\Desktop\mangalib_monster обход блокировки ботов\.venv\lib\site-packages\django\db\models\sql\query.py", line 1198, in add_annotation
    annotation = annotation.resolve_expression(self, allow_joins=True, reuse=None)
  File "c:\Users\Shamrock\Desktop\mangalib_monster обход блокировки ботов\.venv\lib\site-packages\django\db\models\aggregates.py", line 65, in resolve_expression
    c = super().resolve_expression(query, allow_joins, reuse, summarize)
  File "c:\Users\Shamrock\Desktop\mangalib_monster обход блокировки ботов\.venv\lib\site-packages\django\db\models\expressions.py", line 975, in resolve_expression
    c.source_expressions[pos] = arg.resolve_expression(
  File "c:\Users\Shamrock\Desktop\mangalib_monster обход блокировки ботов\.venv\lib\site-packages\django\db\models\expressions.py", line 854, in resolve_expression
    return query.resolve_ref(self.name, allow_joins, reuse, summarize)
  File "c:\Users\Shamrock\Desktop\mangalib_monster обход блокировки ботов\.venv\lib\site-packages\django\db\models\sql\query.py", line 2030, in resolve_ref
    transform = join_info.transform_function(targets[0], final_alias)
  File "c:\Users\Shamrock\Desktop\mangalib_monster обход блокировки ботов\.venv\lib\site-packages\django\db\models\sql\query.py", line 1890, in transform
    return self.try_transform(wrapped, name)
  File "c:\Users\Shamrock\Desktop\mangalib_monster обход блокировки ботов\.venv\lib\site-packages\django\db\models\sql\query.py", line 1427, in try_transform
    raise FieldError(
django.core.exceptions.FieldError: Unsupported lookup 'comment' for PositiveIntegerField or join on the field not permitted.
2024-03-27 04:14:51,591 ERROR Internal Server Error: /api/search/
Traceback (most recent call last):
  File "c:\Users\Shamrock\Desktop\mangalib_monster обход блокировки ботов\.venv\lib\site-packages\django\core\handlers\exception.py", line 55, in inner
    response = get_response(request)
  File "c:\Users\Shamrock\Desktop\mangalib_monster обход блокировки ботов\.venv\lib\site-packages\django\core\handlers\base.py", line 197, in _get_response
    response = wrapped_callback(request, *callback_args, **callback_kwargs)
  File "c:\Users\Shamrock\Desktop\mangalib_monster обход блокировки ботов\.venv\lib\site-packages\django\views\decorators\csrf.py", line 65, in _view_wrapper
    return view_func(request, *args, **kwargs)
  File "c:\Users\Shamrock\Desktop\mangalib_monster обход блокировки ботов\.venv\lib\site-packages\django\views\generic\base.py", line 104, in view
    return self.dispatch(request, *args, **kwargs)
  File "c:\Users\Shamrock\Desktop\mangalib_monster обход блокировки ботов\.venv\lib\site-packages\rest_framework\views.py", line 509, in dispatch
    response = self.handle_exception(exc)
  File "c:\Users\Shamrock\Desktop\mangalib_monster обход блокировки ботов\.venv\lib\site-packages\rest_framework\views.py", line 469, in handle_exception
    self.raise_uncaught_exception(exc)
  File "c:\Users\Shamrock\Desktop\mangalib_monster обход блокировки ботов\.venv\lib\site-packages\rest_framework\views.py", line 480, in raise_uncaught_exception
    raise exc
  File "c:\Users\Shamrock\Desktop\mangalib_monster обход блокировки ботов\.venv\lib\site-packages\rest_framework\views.py", line 506, in dispatch
    response = handler(request, *args, **kwargs)
  File "c:\Users\Shamrock\Desktop\mangalib_monster обход блокировки ботов\.venv\lib\site-packages\rest_framework\decorators.py", line 50, in handler
    return func(*args, **kwargs)
  File "C:\Users\Shamrock\Desktop\mangalib_monster обход блокировки ботов\monster\manga\views.py", line 40, in search
    manga_manager: BaseManager[Manga] = q_search(query).order_by('id')
  File "C:\Users\Shamrock\Desktop\mangalib_monster обход блокировки ботов\monster\manga\utils.py", line 42, in q_search
    result = result.annotate(comments_num=Count('chapters__pages__comment')).filter(comments_num__gt=0)
  File "c:\Users\Shamrock\Desktop\mangalib_monster обход блокировки ботов\.venv\lib\site-packages\django\db\models\query.py", line 1630, in annotate
    return self._annotate(args, kwargs, select=True)
  File "c:\Users\Shamrock\Desktop\mangalib_monster обход блокировки ботов\.venv\lib\site-packages\django\db\models\query.py", line 1680, in _annotate
    clone.query.add_annotation(
  File "c:\Users\Shamrock\Desktop\mangalib_monster обход блокировки ботов\.venv\lib\site-packages\django\db\models\sql\query.py", line 1198, in add_annotation
    annotation = annotation.resolve_expression(self, allow_joins=True, reuse=None)
  File "c:\Users\Shamrock\Desktop\mangalib_monster обход блокировки ботов\.venv\lib\site-packages\django\db\models\aggregates.py", line 65, in resolve_expression
    c = super().resolve_expression(query, allow_joins, reuse, summarize)
  File "c:\Users\Shamrock\Desktop\mangalib_monster обход блокировки ботов\.venv\lib\site-packages\django\db\models\expressions.py", line 975, in resolve_expression
    c.source_expressions[pos] = arg.resolve_expression(
  File "c:\Users\Shamrock\Desktop\mangalib_monster обход блокировки ботов\.venv\lib\site-packages\django\db\models\expressions.py", line 854, in resolve_expression
    return query.resolve_ref(self.name, allow_joins, reuse, summarize)
  File "c:\Users\Shamrock\Desktop\mangalib_monster обход блокировки ботов\.venv\lib\site-packages\django\db\models\sql\query.py", line 2030, in resolve_ref
    transform = join_info.transform_function(targets[0], final_alias)
  File "c:\Users\Shamrock\Desktop\mangalib_monster обход блокировки ботов\.venv\lib\site-packages\django\db\models\sql\query.py", line 1890, in transform
    return self.try_transform(wrapped, name)
  File "c:\Users\Shamrock\Desktop\mangalib_monster обход блокировки ботов\.venv\lib\site-packages\django\db\models\sql\query.py", line 1427, in try_transform
    raise FieldError(
django.core.exceptions.FieldError: Unsupported lookup 'comment' for PositiveIntegerField or join on the field not permitted.
2024-03-27 04:15:17,576 INFO C:\Users\Shamrock\Desktop\mangalib_monster обход блокировки ботов\monster\manga\utils.py changed, reloading.
2024-03-27 04:15:19,306 INFO Watching for file changes with StatReloader
2024-03-27 04:44:42,968 DEBUG Using proactor: IocpProactor
2024-03-27 04:44:44,338 DEBUG Using proactor: IocpProactor
2024-03-27 04:44:49,362 DEBUG Using proactor: IocpProactor
2024-03-27 04:44:54,216 DEBUG Using proactor: IocpProactor
2024-03-27 04:46:39,674 ERROR Internal Server Error: /api/search/
Traceback (most recent call last):
  File "c:\Users\Shamrock\Desktop\mangalib_monster обход блокировки ботов\.venv\lib\site-packages\django\core\handlers\exception.py", line 55, in inner
    response = get_response(request)
  File "c:\Users\Shamrock\Desktop\mangalib_monster обход блокировки ботов\.venv\lib\site-packages\django\core\handlers\base.py", line 220, in _get_response
    response = response.render()
  File "c:\Users\Shamrock\Desktop\mangalib_monster обход блокировки ботов\.venv\lib\site-packages\django\template\response.py", line 114, in render
    self.content = self.rendered_content
  File "c:\Users\Shamrock\Desktop\mangalib_monster обход блокировки ботов\.venv\lib\site-packages\rest_framework\response.py", line 74, in rendered_content
    ret = renderer.render(self.data, accepted_media_type, context)
  File "c:\Users\Shamrock\Desktop\mangalib_monster обход блокировки ботов\.venv\lib\site-packages\rest_framework\renderers.py", line 158, in render
    template_names = self.get_template_names(response, view)
  File "c:\Users\Shamrock\Desktop\mangalib_monster обход блокировки ботов\.venv\lib\site-packages\rest_framework\renderers.py", line 186, in get_template_names
    raise ImproperlyConfigured(
django.core.exceptions.ImproperlyConfigured: Returned a template response with no `template_name` attribute set on either the view or response
2024-03-27 04:46:49,327 WARNING Not Found: /images/placeholders/background.jpeg
2024-03-27 04:47:55,907 ERROR Internal Server Error: /api/search/
Traceback (most recent call last):
  File "c:\Users\Shamrock\Desktop\mangalib_monster обход блокировки ботов\.venv\lib\site-packages\django\core\handlers\exception.py", line 55, in inner
    response = get_response(request)
  File "c:\Users\Shamrock\Desktop\mangalib_monster обход блокировки ботов\.venv\lib\site-packages\django\core\handlers\base.py", line 220, in _get_response
    response = response.render()
  File "c:\Users\Shamrock\Desktop\mangalib_monster обход блокировки ботов\.venv\lib\site-packages\django\template\response.py", line 114, in render
    self.content = self.rendered_content
  File "c:\Users\Shamrock\Desktop\mangalib_monster обход блокировки ботов\.venv\lib\site-packages\rest_framework\response.py", line 74, in rendered_content
    ret = renderer.render(self.data, accepted_media_type, context)
  File "c:\Users\Shamrock\Desktop\mangalib_monster обход блокировки ботов\.venv\lib\site-packages\rest_framework\renderers.py", line 158, in render
    template_names = self.get_template_names(response, view)
  File "c:\Users\Shamrock\Desktop\mangalib_monster обход блокировки ботов\.venv\lib\site-packages\rest_framework\renderers.py", line 186, in get_template_names
    raise ImproperlyConfigured(
django.core.exceptions.ImproperlyConfigured: Returned a template response with no `template_name` attribute set on either the view or response
2024-03-27 04:48:10,375 INFO C:\Users\Shamrock\Desktop\mangalib_monster обход блокировки ботов\monster\manga\utils.py changed, reloading.
2024-03-27 04:48:11,614 INFO Watching for file changes with StatReloader
